Workbook

Sheet Component Master
A1: Categories | B1: CID/SKU Number | C1: Components | D1: Specification | E1: Vendor | F1: Last Updated Price | G1: Last Updated Date | H1: UOM | I1: Vajra | J1: Astra | K1: Bhima | L1: Vyoma | M1: Chakra | N1: Agri | O1: Availability | P1: Project 1- P0001 | Q1: Project 2- P0002 | R1: Project 3- P0003 | S1: Effective Inventory
A2: Airframe | B2: Aero0001 | C2: Carry case | D2: Bhima_Carrycase_with_Foam | E2: Aerotek | F2: 28674 | G2: 45383 | H2: Nos | I2: No | J2: No | K2: 1 | L2: No | M2: No | N2: No | O2: 2 | S2: =O2-P2-Q2-R2 -> 2
A3: Airframe | B3: Aero0002 | C3: Carry case | D3: Vajra_Carrycase_with_Foam | E3: Paxshell | F3: 23482 | G3: 45362 | H3: Nos | I3: 1 | J3: No | K3: No | L3: No | M3: No | N3: No | O3: 0 | S3: =O3-P3-Q3-R3 -> 0
A4: Airframe | B4: Aero0003 | C4: Carry case | D4: Astra Carry case with Foam | E4: Paxshell | F4: 14514 | G4: 45330 | H4: Nos | I4: No | J4: 1 | K4: No | L4: No | M4: No | N4: No | O4: 0 | S4: =O4-P4-Q4-R4 -> 0
A5: Airframe | B5: Aero0004 | C5: Carry case | D5: Agri Carry case with Foam | E5: Aerotek | F5: 32450 | G5: 45383 | H5: Nos | I5: No | J5: No | K5: No | L5: No | M5: No | N5: 1 | O5: 0 | S5: =O5-P5-Q5-R5 -> 0
A6: Airframe | B6: Aero0005 | C6: Carry case | D6: For Nano Drone | E6: Aerotek | F6: 5000 | G6: 45334 | H6: Nos | I6: No | J6: No | K6: No | L6: No | M6: 1 | N6: No | O6: 0 | S6: =O6-P6-Q6-R6 -> 0
A7: Airframe | B7: Aero0006 | C7: CF Sheet | D7: 400mm * 300mm * 1mm | E7: Hindustan Engineers | F7: 1420 | G7: 45391 | H7: Nos | I7: Project Specfic | J7: Project Specfic | K7: Project Specfic | L7: Project Specfic | M7: Project Specfic | N7: Project Specfic | O7: 1 | S7: =O7-P7-Q7-R7 -> 1
A8: Airframe | B8: Aero0007 | C8: CF Sheet | D8: 130mm * 90mm * 1mm | E8: Hindustan Engineers | F8: 138 | G8: 45406 | H8: Nos | I8: Project Specfic | J8: Project Specfic | K8: Project Specfic | L8: Project Specfic | M8: Project Specfic | N8: Project Specfic | O8: 1 | P8: 1 | S8: =O8-P8-Q8-R8 -> 0
A9: Airframe | B9: Aero0008 | C9: CF Sheet | D9: 125mm * 75mm * 3mm | E9: Hindustan Engineers | F9: 303 | G9: 45406 | H9: Nos | I9: Project Specfic | J9: Project Specfic | K9: Project Specfic | L9: Project Specfic | M9: Project Specfic | N9: Project Specfic | O9: 1 | Q9: 1 | S9: =O9-P9-Q9-R9 -> 0
A10: Airframe | B10: Aero0009 | C10: CF Sheet | D10: 300mm * 200mm * 2mm | E10: Hindustan Engineers | F10: 1291 | G10: 45406 | H10: Nos | I10: Project Specfic | J10: Project Specfic | K10: Project Specfic | L10: Project Specfic | M10: Project Specfic | N10: Project Specfic | O10: 1 | Q10: 1 | S10: =O10-P10-Q10-R10 -> 0
A11: Airframe | B11: Aero0010 | C11: CF Sheet | D11: 300mm * 200mm * 3mm | E11: Hindustan Engineers | F11: 1937 | G11: 45406 | H11: Nos | I11: Project Specfic | J11: Project Specfic | K11: Project Specfic | L11: Project Specfic | M11: Project Specfic | N11: Project Specfic | O11: 3 | Q11: 1 | S11: =O11-P11-Q11-R11 -> 2
A12: Airframe | B12: Aero0011 | C12: CF Sheet | D12: 100mm * 250mm * 4mm | E12: Hindustan Engineers | F12: 1076 | G12: 45406 | H12: Nos | I12: Project Specfic | J12: Project Specfic | K12: Project Specfic | L12: Project Specfic | M12: Project Specfic | N12: Project Specfic | O12: 2 | S12: =O12-P12-Q12-R12 -> 2
A13: Airframe | B13: Aero0012 | C13: CF Sheet | D13: 400mm * 400mm * 4mm | E13: Hindustan Engineers | F13: 6886 | G13: 45406 | H13: Nos | I13: Project Specfic | J13: Project Specfic | K13: Project Specfic | L13: Project Specfic | M13: Project Specfic | N13: Project Specfic | O13: 4 | P13: 4 | S13: =O13-P13-Q13-R13 -> 0
A14: Airframe | B14: Aero0013 | C14: CF Hollow Tube | D14: CF Tube 30mm OD * 27mm ID * 550mm | E14: Hindustan Engineers | F14: 2247 | G14: 45391 | H14: Nos | I14: No | J14: No | K14: No | L14: No | M14: No | N14: 6 | O14: 0 | S14: =O14-P14-Q14-R14 -> 0
A15: Airframe | B15: Aero0014 | C15: CF Hollow Tube | D15: CF Tube 6mm OD * 4mm ID * 1000mm | E15: Think Robotics | F15: 759.99 | G15: 45407 | H15: Nos | I15: 2 | J15: No | K15: No | L15: No | M15: No | N15: No | O15: 2 | Q15: 2 | S15: =O15-P15-Q15-R15 -> 0
A16: Airframe | B16: Aero0015 | C16: CF Square Tube | D16: CF Sq Tube 15mm * 13mm * 1000mm/Gloss | E16: Think Robotics | F16: 4399.99 | G16: 45407 | H16: Nos | I16: 2 | J16: No | K16: No | L16: No | M16: No | N16: No | O16: 2 | Q16: 2 | S16: =O16-P16-Q16-R16 -> 0
A17: Airframe | B17: Aero0016 | C17: Spacers | D17: 50 mm spacer (Pack of 20) | E17: Local | F17: 700 | G17: - | H17: Pack | I17: Yes | J17: Yes | K17: Yes | L17: No | M17: No | N17: No | O17: 1 | S17: =O17-P17-Q17-R17 -> 1
A18: Airframe | B18: Aero0017 | C18: Spacers | D18: 20mm Spacer(Pack of 25) | E18: Macfos | F18: 550 | G18: 45411 | H18: Pack | I18: Yes | J18: Yes | K18: Yes | L18: No | M18: No | N18: No | O18: 0 | S18: =O18-P18-Q18-R18 -> 0
A19: Airframe | B19: Aero0018 | C19: Spacers | D19: 10 mm spacer (Pack of 20) | E19: Local | F19: 550 | G19: - | H19: Pack | I19: Yes | J19: Yes | K19: Yes | L19: No | M19: No | N19: No | O19: 1 | S19: =O19-P19-Q19-R19 -> 1
A20: Airframe | B20: Aero0019 | C20: Spacers | D20: Spacers 40mm female to female | E20: Local | F20: 350 | G20: - | H20: Pack | I20: Yes | J20: Yes | K20: No | L20: No | M20: No | N20: No | O20: 1 | S20: =O20-P20-Q20-R20 -> 1
A21: Airframe | B21: Aero0020 | C21: Shock Absorber | D21: Pixhawk Dampner plate | E21: Macfos | F21: 144.07 | G21: 45412 | H21: Nos | I21: Yes | J21: Yes | K21: No | L21: No | M21: No | N21: 1 | O21: 1 | S21: =O21-P21-Q21-R21 -> 1
A22: Airframe | B22: Aero0021 | C22: Frame | D22: NANO-Rekon 4 FR Freestyle Frame Kit 4 Inches Frame | E22: Quadkart | F22: 7499 | G22: 45381 | H22: Nos | I22: No | J22: No | K22: No | L22: No | M22: 1 | N22: No | O22: 1 | S22: =O22-P22-Q22-R22 -> 1
A23: Airframe | B23: Aero0022 | C23: Frame | D23: M1500 | E23: T-Drones | F23: 450000 | G23: 45342 | H23: Nos | I23: No | J23: No | K23: 1 | L23: No | M23: No | N23: No | O23: 2 | S23: =O23-P23-Q23-R23 -> 2
A24: Airframe | B24: Aero0023 | C24: Frame | D24: M690 Pro | E24: T-Drones | F24: 210000 | G24: 45339 | H24: Nos | I24: No | J24: 1 | K24: No | L24: No | M24: No | N24: No | O24: 0 | S24: =O24-P24-Q24-R24 -> 0
A25: Airframe | B25: Aero0024 | C25: Frame | D25: Vyoma Airframe | E25: Arace | F25: 1903381.9 | G25: 45308 | H25: Nos | I25: No | J25: No | K25: No | L25: 1 | M25: No | N25: No | O25: 2 | S25: =O25-P25-Q25-R25 -> 2
A26: Airframe | B26: Aero0025 | C26: Landing gear | D26: M1500 | E26: T-Drones | F26: 18765.24 | G26: 45308 | H26: Nos | I26: No | J26: No | K26: 2 | L26: No | M26: No | N26: No | O26: 4 | S26: =O26-P26-Q26-R26 -> 4
A27: Airframe | B27: Aero0026 | C27: Manpack | D27: Waterproof manpack | E27: Aerotek | F27: 13750 | G27: 45339 | H27: Nos | I27: No | J27: No | K27: No | L27: 1 | M27: No | N27: No | O27: 2 | S27: =O27-P27-Q27-R27 -> 2
A28: Airframe | B28: Aero0027 | C28: Water Jet cutting | D28: Alind water jet cutting | E28: Alind | F28: 5000 | G28: - | H28: Nos | I28: Project Specfic | J28: Project Specfic | K28: Project Specfic | L28: Project Specfic | M28: Project Specfic | N28: Project Specfic | O28: 0 | S28: =O28-P28-Q28-R28 -> 0
A29: Airframe | B29: Aero0028 | C29: 3D Printed Parts | D29: Canopy | E29: Amuse | F29: 10000 | G29: - | H29: Nos | I29: 1 | J29: No | K29: No | L29: No | M29: No | N29: 1 | O29: 0 | S29: =O29-P29-Q29-R29 -> 0
A30: Airframe | B30: Aero0029 | C30: 3D Printed Parts | D30: 3D Printed Parts | E30: Amuse | F30: 30000 | G30: - | H30: Nos | I30: Project Specfic | J30: Project Specfic | K30: Project Specfic | L30: Project Specfic | M30: Project Specfic | N30: Project Specfic | O30: 0 | S30: =O30-P30-Q30-R30 -> 0
A31: Communication | B31: Aero0030 | C31: Remote controller | D31: Skydroid H12 | E31: Robokits | F31: 30421.58 | G31: 45391 | H31: Nos | I31: Yes | J31: No | K31: No | L31: No | M31: No | N31: 1 | O31: 0 | S31: =O31-P31-Q31-R31 -> 0
A32: Communication | B32: Aero0031 | C32: Remote controller | D32: SIYI MK15 AGRI Version | E32: Robokits | F32: 48287.96 | G32: 45414 | H32: Nos | I32: No | J32: No | K32: No | L32: No | M32: No | N32: 1 | O32: 2 | P32: 2 | S32: =O32-P32-Q32-R32 -> 0
A33: Communication | B33: Aero0032 | C33: Remote controller | D33: Logitech Joystick | E33: Local | F33: 2500 | G33: - | H33: Nos | I33: Yes | J33: Yes | K33: No | L33: Yes | M33: No | N33: No | O33: 2 | S33: =O33-P33-Q33-R33 -> 2
A34: Communication | B34: Aero0033 | C34: Remote controller | D34: SIYI HM30 | E34: Robokits | F34: 29404.42 | G34: 45414 | H34: Nos | I34: Yes | J34: Yes | K34: No | L34: No | M34: No | N34: No | O34: 1 | S34: =O34-P34-Q34-R34 -> 1
A35: Communication | B35: Aero0034 | C35: Remote controller | D35: Skydroid H16 | E35: Indian Robo Store | F35: 89999 | G35: 45414 | H35: Nos | I35: Yes | J35: Yes | K35: Yes | L35: Yes | M35: No | N35: No | O35: 3 | S35: =O35-P35-Q35-R35 -> 3
A36: Communication | B36: Aero0035 | C36: Remote controller | D36: Skydroid H16 Pro | E36: Indian Robo Store | F36: 138999 | G36: 45414 | H36: Nos | I36: Yes | J36: Yes | K36: Yes | L36: Yes | M36: No | N36: No | O36: 0 | S36: =O36-P36-Q36-R36 -> 0
A37: Communication | B37: Aero0036 | C37: Remote controller | D37: SIYI MK15 | E37: Indian Robo Store | F37: 79999 | G37: 45414 | H37: Nos | I37: Yes | J37: Yes | K37: Yes | L37: Yes | M37: No | N37: No | O37: 1 | S37: =O37-P37-Q37-R37 -> 1
A38: Communication | B38: Aero0037 | C38: Remote controller | D38: Skydroid T12 | E38: Indian Robo Store | F38: 23999 | G38: 45414 | H38: Nos | I38: Yes | J38: Yes | K38: Yes | L38: Yes | M38: No | N38: 1 | O38: 0 | S38: =O38-P38-Q38-R38 -> 0
A39: Communication | B39: Aero0038 | C39: RF communication | D39: Doodle Labs RM-2450-12M3 | E39: Aqtronics | F39: 209632.9 | G39: 45381 | H39: Nos | I39: Yes | J39: Yes | K39: No | L39: 3 | M39: No | N39: No | O39: 6 | S39: =O39-P39-Q39-R39 -> 6
A40: Communication | B40: Aero0039 | C40: RF communication | D40: Evaluation Kit | E40: Aqtronics | F40: 41134.46 | G40: 45381 | H40: Nos | I40: Yes | J40: Yes | K40: No | L40: 3 | M40: No | N40: No | O40: 6 | S40: =O40-P40-Q40-R40 -> 6
...

Sheet Order Tracker
A1: S.No | B1: Date | C1: PO # | D1: CID/SKU Number | E1: Description | F1: Qty | G1: Vendor | H1: Unit Price | I1: Sub Total | J1: GST | K1: Shipping | L1: Total Price | M1: Quote | N1: Project | O1: Status | P1: Warranty terms | Q1: Remarks
A2: 1 | B2: 45425 | D2: Aero0170 | E2: EFT E610P Airframe with 10L Tank | F2: 1 | G2: Macfos | H2: 38903.81 | I2: =F2*H2 -> 38903.81 | J2: =0.05*I2 -> 1945.1905 | K2: 600 | L2: =SUM(I2:K2) -> 41449.001 | M2: Link | N2: NRSC | O2: Received
A3: 2 | B3: 45425 | D3: Aero0171 | E3: =VLOOKUP(D3,'Component Master'!B:D,3,0) -> CF Sheet 500*500mm*3mm | F3: 2 | G3: Macfos | H3: 7316.95 | I3: =F3*H3 -> 14633.9 | J3: =0.18*I3 -> 2634.102 | K3: 600 | L3: =SUM(I3:K3) -> 17868.002 | M3: Link | N3: AGRI-P0001 | O3: Received
A4: 3 | B4: 45425 | D4: Aero0162 | E4: =VLOOKUP(D4,'Component Master'!B:D,3,0) -> 400mm*380mm*3mm | F4: 2 | G4: Hindustan Engineers | H4: 4907 | I4: =F4*H4 -> 9814 | J4: =0.18*I4 -> 1766.52 | K4: 0 | L4: =SUM(I4:K4) -> 11580.52 | M4: Link | N4: AGRI-P0001 | O4: Received
A5: 4 | B5: 45425 | D5: - | E5: Customization & Setup of Trans-receiver | F5: 1 | G5: Apico | H5: 75000 | I5: =F5*H5 -> 75000 | J5: =0.18*I5 -> 13500 | K5: 0 | L5: =SUM(I5:K5) -> 88500 | M5: Link | N5: AGRI-P0001 | O5: Received
A6: 5 | B6: 45425 | D6: Aero0169 | E6: Drone Trans-receiver | F6: 2 | G6: Apico | H6: 38000 | I6: =F6*H6 -> 76000 | J6: =0.18*I6 -> 13680 | K6: 0 | L6: =SUM(I6:K6) -> 89680 | M6: Link | N6: AGRI-P0001 | O6: Received
A7: 6 | B7: 45426 | D7: Aero0172 | E7: Aluminium mount | F7: 12 | G7: Aerotek | H7: 4000 | I7: =F7*H7 -> 48000 | J7: =0.18*I7 -> 8640 | K7: 0 | L7: =SUM(I7:K7) -> 56640 | M7: Link | N7: AGRI-P0001 | O7: Received
A8: 7 | B8: 45426 | D8: Aero0173 | E8: Hall Sensor | F8: 3 | G8: Vyom Drones | H8: 4420 | I8: =F8*H8 -> 13260 | J8: =0.05*I8 -> 663 | K8: 0 | L8: =SUM(I8:K8) -> 13923 | M8: Link | N8: AGRI-P0001 | O8: Received
A9: 8 | B9: 45427 | D9: Aero0181 | E9: Mauch 084: 4-14S BEC | F9: 2 | G9: Vyom Drones | H9: 3900 | I9: =F9*H9 -> 7800 | J9: =0.05*I9 -> 390 | K9: 0 | L9: =SUM(I9:K9) -> 8190 | M9: Link | N9: AGRI-P0001 | O9: Received
A10: 9 | B10: 45427 | D10: Aero0182 | E10: Mauch 086: Adapter cable for Pixhawk 2 | F10: 2 | G10: Vyom Drones | H10: 500 | I10: =F10*H10 -> 1000 | J10: =0.05*I10 -> 50 | K10: 0 | L10: =SUM(I10:K10) -> 1050 | M10: Link | N10: AGRI-P0001 | O10: Received
A11: 10 | B11: 45427 | D11: Aero0183 | E11: Water flow sensor-White | F11: 2 | G11: Macfos | H11: 224 | I11: =F11*H11 -> 448 | J11: 0 | K11: =49+25 -> 74 | L11: =SUM(I11:K11) -> 522 | M11: Link | N11: AGRI-P0001 | O11: Received | Q11: Online order/COD
A12: 11 | B12: 45428 | D12: Aero0029 | E12: Lug Connector | F12: 2 | G12: Amuse | H12: 282.9 | I12: =F12*H12 -> 565.8 | J12: =0.18*I12 -> 101.844 | K12: 0 | L12: =SUM(I12:K12) -> 667.644 | M12: Link | N12: AGRI-P0001 | O12: Received
A13: 12 | B13: 45428 | D13: Aero0029 | E13: PCB Enclosure | F13: 2 | G13: Amuse | H13: 2492.8 | I13: =F13*H13 -> 4985.6 | J13: =0.18*I13 -> 897.408 | K13: 0 | L13: =SUM(I13:K13) -> 5883.008 | M13: Link | N13: AGRI-P0001 | O13: Received
A14: 13 | B14: 45429 | D14: Aero0029 | E14: Canopy | F14: 1 | G14: Nextgen | H14: 21750 | I14: =F14*H14 -> 21750 | J14: =0.18*I14 -> 3915 | K14: 100 | L14: =SUM(I14:K14) -> 25765 | M14: Link | N14: AGRI-P0001 | O14: Received
A15: 14 | B15: 45429 | D15: Aero0029 | E15: Sidewall | F15: 1 | G15: Nextgen | H15: 6300 | I15: =F15*H15 -> 6300 | J15: =0.18*I15 -> 1134 | K15: 100 | L15: =SUM(I15:K15) -> 7534 | M15: Link | N15: AGRI-P0001 | O15: Received
A16: 15 | B16: 45429 | D16: - | E16: Calibration Testing(NABL certification) | F16: 1 | G16: Dynamic Calibration | H16: 5900 | I16: =F16*H16 -> 5900 | J16: =0.18*I16 -> 1062 | K16: 0 | L16: =SUM(I16:K16) -> 6962 | M16: Link | N16: AGRI-P0001 | O16: Received
A17: 16 | B17: 45434 | D17: Aero0027 | E17: =VLOOKUP(D17,'Component Master'!B6:D189,3,0) -> Alind water jet cutting | F17: 2 | G17: Alind | H17: 1079 | I17: =F17*H17 -> 2158 | J17: =0.12*I17 -> 258.96 | K17: 0 | L17: =SUM(I17:K17) -> 2416.96 | M17: Link | N17: AGRI-P0001 | O17: Received
A18: 17 | B18: 45434 | D18: Aero0027 | E18: =VLOOKUP(D18,'Component Master'!B7:D190,3,0) -> Alind water jet cutting | F18: 2 | G18: Alind | H18: 1100 | I18: =F18*H18 -> 2200 | J18: =0.12*I18 -> 264 | K18: 0 | L18: =SUM(I18:K18) -> 2464 | M18: Link | N18: AGRI-P0001 | O18: Received
A19: 18 | B19: 45435 | D19: Aero0184 | E19: =VLOOKUP(D19,'Component Master'!B8:D191,3,0) -> Liquid water Level sensor | F19: 3 | G19: Macfos | H19: 508.47 | I19: =F19*H19 -> 1525.41 | J19: =0.18*I19 -> 274.5738 | K19: 62 | L19: =SUM(I19:K19) -> 1861.9838 | M19: Link | N19: AGRI-P0001 | O19: Received
A20: 19 | B20: 45435 | D20: Aero0183 | E20: =VLOOKUP(D20,'Component Master'!B9:D192,3,0) -> Water flow sensor-White | F20: 1 | G20: Macfos | H20: 224 | I20: =F20*H20 -> 224 | J20: 0 | K20: 62 | L20: =SUM(I20:K20) -> 286 | M20: Link | N20: AGRI-P0001 | O20: Received
A21: 20 | B21: 45435 | D21: Aero0004 | E21: =VLOOKUP(D21,'Component Master'!B2:D194,3,0) -> Agri Carry case with Foam | F21: 2 | G21: Aerotek | H21: 10750 | I21: =F21*H21 -> 21500 | J21: =0.18*I21 -> 3870 | K21: 0 | L21: =SUM(I21:K21) -> 25370 | M21: Link | N21: AGRI-P0001 | O21: Received
A22: 21 | B22: 45435 | D22: Aero0180 | E22: =VLOOKUP(D22,'Component Master'!B3:D195,3,0) -> GPS Stand-Agri | F22: 2 | G22: Elecdrone Technologies | H22: 380 | I22: =F22*H22 -> 760 | J22: =0.05*I22 -> 38 | K22: 0 | L22: =SUM(I22:K22) -> 798 | M22: Link | N22: AGRI-P0001 | O22: Received
A23: 22 | B23: 45435 | D23: Aero0172 | E23: =VLOOKUP(D23,'Component Master'!B4:D196,3,0) -> Aluminium mount | F23: 12 | G23: Aerotek | H23: 2750 | I23: =F23*H23 -> 33000 | J23: 6048 | K23: 600 | L23: =SUM(I23:K23) -> 39648 | M23: Link | N23: AGRI-P0001 | O23: Received
A24: 23 | B24: 45435 | D24: Aero0110 | E24: =VLOOKUP(D24,'Component Master'!B5:D197,3,0) -> Pump,Nozzle,Hose & Pneumatic Connectors | F24: 1 | G24: Elecdrone Technologies | H24: 6048 | I24: =F24*H24 -> 6048 | J24: =0.05*I24 -> 302.4 | K24: 0 | L24: =SUM(I24:K24) -> 6350.4 | M24: Link | N24: AGRI-P0001 | O24: Received
A25: 24 | B25: 45436 | C25: 03/24-25 | D25: Aero0029 | E25: Canopy | F25: 1 | G25: Monotech | H25: 16425 | I25: =F25*H25 -> 16425 | J25: =0.18*I25 -> 2956.5 | K25: 0 | L25: =SUM(I25:K25) -> 19381.5 | M25: Link | N25: AGRI-P0001 | O25: Received
A26: 25 | B26: 45436 | D26: Aero0027 | E26: =VLOOKUP(D26,'Component Master'!B7:D199,3,0) -> Alind water jet cutting | F26: 1 | G26: Alind | H26: 1100 | I26: =F26*H26 -> 1100 | J26: =0.12*I26 -> 132 | K26: 0 | L26: =SUM(I26:K26) -> 1232 | M26: Link | N26: AGRI-P0001 | O26: Received
A27: 26 | B27: 45436 | D27: Aero0185 | E27: =VLOOKUP(D27,'Component Master'!B8:D200,3,0) -> QS8-S Anti spark Male/Female connector pair | F27: 2 | G27: Macfos | H27: 669 | I27: =F27*H27 -> 1338 | J27: 0 | K27: 0 | L27: =SUM(I27:K27) -> 1338 | M27: Link | N27: AGRI-P0001 | O27: Received
A28: 27 | B28: 45439 | D28: - | E28: MX860 | F28: 1 | G28: T-Drones | H28: 249961.4 | I28: =F28*H28 -> 249961.4 | J28: 0 | K28: 0 | L28: =SUM(I28:K28) -> 249961.4 | M28: Link | O28: - | Q28: For Price validation
A29: 28 | B29: 45439 | D29: - | E29: M1200 | F29: 1 | G29: T-Drones | H29: 241626.58 | I29: =F29*H29 -> 241626.58 | J29: 0 | K29: 0 | L29: =SUM(I29:K29) -> 241626.58 | M29: Link | O29: - | Q29: For Price validation
A30: 29 | B30: 45439 | D30: Aero0029 | E30: Bottom Plate-sensor Holder | F30: 2 | G30: Amuse | H30: =425.7 -> 425.7 | I30: =F30*H30 -> 851.4 | J30: 188.34 | K30: 225 | L30: =SUM(I30:K30) -> 1264.74 | M30: Link | N30: AGRI-P0001 | O30: Received
A31: 30 | B31: 45439 | D31: Aero0029 | E31: Top Plate- Sensor Holder | F31: 2 | G31: Amuse | H31: 395.6 | I31: =F31*H31 -> 791.2 | J31: 188.34 | K31: 225 | L31: =SUM(I31:K31) -> 1204.54 | M31: Link | N31: AGRI-P0001 | O31: Received
A32: 31 | B32: 45439 | D32: Aero0029 | E32: Canopy | F32: 2 | G32: Nextgen | H32: 21920 | I32: =F32*H32 -> 43840 | J32: =0.18*I32 -> 7891.2 | K32: 118 | L32: =SUM(I32:K32) -> 51849.2 | M32: Link | N32: AGRI-P0001 | O32: Received
A33: 32 | B33: 45439 | D33: Aero0029 | E33: Sidewall | F33: 1 | G33: Nextgen | H33: 6300 | I33: =F33*H33 -> 6300 | J33: =0.18*I33 -> 1134 | K33: 118 | L33: =SUM(I33:K33) -> 7552 | M33: Link | N33: AGRI-P0001 | O33: Received
A34: 33 | B34: 45440 | D34: - | E34: Calibration Testing(NABL certification) | F34: 1 | G34: Dynamic Calibration | H34: 0 | I34: =F34*H34 -> 0 | J34: =0.18*I34 -> 0 | K34: 0 | L34: =SUM(I34:K34) -> 0 | N34: AGRI-P0001 | O34: Received
A35: 34 | B35: 45440 | D35: Aero0186 | E35: =VLOOKUP(D35,'Component Master'!B16:D208,3,0) -> Tattu 22000mAh 6S Lipo Battery | F35: 4 | G35: Elecdrone Technologies | H35: 18000 | I35: =F35*H35 -> 72000 | J35: =0.18*I35 -> 12960 | K35: 0 | L35: =SUM(I35:K35) -> 84960 | M35: - | N35: AGRI-P0001 | O35: Received
A36: 35 | B36: 45440 | D36: - | E36: Portable Generator | F36: - | G36: - | H36: 0 | I36: 0 | J36: =0.18*I36 -> 0 | K36: 0 | L36: =SUM(I36:K36) -> 0 | M36: - | N36: AGRI-P0001 | O36: Yet to Place | Q36: Waiting for Tech team confirmation
A37: 36 | B37: 45444 | D37: Aero0027 | E37: =VLOOKUP(D37,'Component Master'!B17:D209,3,0) -> Alind water jet cutting | F37: 2 | G37: Alind | H37: 542 | I37: =F37*H37 -> 1084 | J37: =0.12*I37 -> 130.08 | K37: 0 | L37: =SUM(I37:K37) -> 1214.08 | N37: AGRI-P0001 | O37: Received
A38: 37 | B38: 45447 | D38: Aero0115 | E38: =VLOOKUP(D38,'Component Master'!B18:D210,3,0) -> 10L Tank | F38: 1 | G38: Elecdrone Technologies | H38: 6860 | I38: =F38*H38 -> 6860 | J38: =0.05*I38 -> 343 | K38: 0 | L38: =SUM(I38:K38) -> 7203 | N38: AGRI-P0001 | O38: Received
A39: 38 | B39: 45447 | D39: Aero0185 | E39: =VLOOKUP(D39,'Component Master'!B19:D211,3,0) -> QS8-S Anti spark Male/Female connector pair | F39: 6 | G39: Macfos | H39: 558.06 | I39: =F39*H39 -> 3348.36 | J39: =0.18*I39 -> 602.7048 | K39: 49 | L39: =SUM(I39:K39) -> 4000.0648 | N39: AGRI-P0001 | O39: Received
A40: 39 | B40: 45448 | D40: Aero0187 | E40: FrSky 900MHz Super 8 Antenna for R9M and R9M Lite Module_ FCC version | F40: 1 | G40: Macfos | H40: 1100.85 | I40: =F40*H40 -> 1100.85 | J40: =0.18*I40 -> 198.153 | K40: 0 | L40: =SUM(I40:K40) -> 1299.003 | N40: NANO | O40: Received | Q40: Online order/COD
...

Sheet Inward
A1: Date | B1: CID/SKU Number | C1: Specification | D1: Qty | E1: Vendor | F1: Invoice Date | G1: Unit Price | H1: Subtotal | I1: GST | J1: Shipping | K1: Total Price | L1: Project
A2: 45414 | B2: Aero0092 | C2: =VLOOKUP(B2,'Component Master'!B:D,3,0) -> Here3+ | D2: 3 | E2: Vyom Drones | F2: 45411 | G2: 20000 | H2: =G2*D2 -> 60000 | I2: =0.05*H2 -> 3000 | J2: 0 | K2: =H2+I2+J2 -> 63000 | L2: P0002
A3: 45414 | B3: Aero0162 | C3: =VLOOKUP(B3,'Component Master'!B:D,3,0) -> 400mm*380mm*3mm | D3: 4 | E3: Hindustan Engineers | F3: 45414 | G3: 4907 | H3: =G3*D3 -> 19628 | I3: =0.05*H3 -> 981.4 | J3: 0 | K3: =H3+I3+J3 -> 20609.4 | L3: P0001
A4: 45416 | B4: Aero0163 | C4: =VLOOKUP(B4,'Component Master'!B:D,3,0) -> 3.5mm Male Female Banana Plug Bullet Connector (Pack of 10) | D4: 2 | E4: Robocraze | F4: 45411 | G4: 217 | H4: =G4*D4 -> 434 | I4: 0 | J4: 100 | K4: =H4+I4+J4 -> 534 | L4: P0002
A5: 45416 | B5: Aero0164 | C5: =VLOOKUP(B5,'Component Master'!B:D,3,0) -> Amass XT90E-M male connector | D5: 1 | E5: Flyrobo | F5: 45413 | G5: 83.9 | H5: =G5*D5 -> 83.9 | I5: =0.18*H5 -> 15.102 | J5: 79 | K5: =H5+I5+J5 -> 178.002 | L5: P0002
A6: 45418 | B6: Aero0066 | C6: =VLOOKUP(B6,'Component Master'!B:D,3,0) -> Air 40 Amps | D6: 8 | E6: Vyom Drones | F6: 45414 | G6: 2800 | H6: =G6*D6 -> 22400 | I6: =0.05*H6 -> 1120 | J6: 0 | K6: =H6+I6+J6 -> 23520 | L6: P0002
A7: 45418 | B7: Aero0087 | C7: =VLOOKUP(B7,'Component Master'!B:D,3,0) -> PIXHAWK_CUBE Orange+ with ADSB Set | D7: 3 | E7: Vyom Drones | F7: 45415 | G7: 30000 | H7: =G7*D7 -> 90000 | I7: =0.05*G7 -> 1500 | J7: 0 | K7: =H7+I7+J7 -> 91500 | L7: P0001& P0002
A8: 45419 | B8: Aero0027 | C8: =VLOOKUP(B8,'Component Master'!B:D,3,0) -> Alind water jet cutting | D8: 1 | E8: Alind | F8: 45419 | G8: 1013 | H8: =G8*D8 -> 1013 | I8: =0.12*H8 -> 121.56 | J8: 0 | K8: =H8+I8+J8 -> 1134.56 | L8: P0001
A9: 45419 | B9: Aero0027 | C9: =VLOOKUP(B9,'Component Master'!B:D,3,0) -> Alind water jet cutting | D9: 4 | E9: Alind | F9: 45419 | G9: 1052 | H9: =G9*D9 -> 4208 | I9: =0.12*H9 -> 504.96 | J9: 0 | K9: =H9+I9+J9 -> 4712.96 | L9: P0001
A10: 45419 | B10: Aero0027 | C10: =VLOOKUP(B10,'Component Master'!B:D,3,0) -> Alind water jet cutting | D10: 4 | E10: Alind | F10: 45419 | G10: 1048 | H10: =G10*D10 -> 4192 | I10: =0.12*H10 -> 503.04 | J10: 0 | K10: =H10+I10+J10 -> 4695.04 | L10: P0001
A11: 45419 | B11: Aero0027 | C11: =VLOOKUP(B11,'Component Master'!B:D,3,0) -> Alind water jet cutting | D11: 8 | E11: Alind | F11: 45419 | G11: 1632 | H11: =G11*D11 -> 13056 | I11: =0.12*H11 -> 1566.72 | J11: 0 | K11: =H11+I11+J11 -> 14622.72 | L11: P0001
A12: 45419 | B12: Aero0027 | C12: =VLOOKUP(B12,'Component Master'!B:D,3,0) -> Alind water jet cutting | D12: 1 | E12: Alind | F12: 45419 | G12: 896 | H12: =G12*D12 -> 896 | I12: =0.12*H12 -> 107.52 | J12: 0 | K12: =H12+I12+J12 -> 1003.52 | L12: P0001
A13: 45421 | B13: Aero0178 | C13: =VLOOKUP(B13,'Component Master'!B:D,3,0) -> Hobbywing X6 Pro motor CW | D13: 3 | E13: Elecdrones Technologies | F13: 45421 | G13: 13900 | H13: =G13*D13 -> 41700 | I13: =0.05*H13 -> 2085 | J13: 0 | K13: =H13+I13+J13 -> 43785 | L13: P0003
A14: 45421 | B14: Aero0179 | C14: =VLOOKUP(B14,'Component Master'!B:D,3,0) -> Hobbywing X6 Pro motor CCW | D14: 3 | E14: Elecdrones Technologies | F14: 45421 | G14: 13900 | H14: =G14*D14 -> 41700 | I14: =0.05*H14 -> 2085 | J14: 0 | K14: =H14+I14+J14 -> 43785 | L14: P0003
A15: 45421 | B15: Aero0165 | C15: =VLOOKUP(B15,'Component Master'!B:D,3,0) -> 2388 inch Propellers | D15: 9 | E15: Elecdrones Technologies | F15: 45421 | G15: 1413 | H15: =G15*D15 -> 12717 | I15: =0.05*H15 -> 635.85 | J15: 0 | K15: =H15+I15+J15 -> 13352.85 | L15: P0003
A16: 45421 | B16: Aero0180 | C16: =VLOOKUP(B16,'Component Master'!B:D,3,0) -> GPS Stand-Agri | D16: 1 | E16: Elecdrones Technologies | F16: 45421 | G16: 388 | H16: =G16*D16 -> 388 | I16: =0.05*H16 -> 19.4 | J16: 0 | K16: =H16+I16+J16 -> 407.4 | L16: P0001
A17: 45422 | B17: Aero0152 | C17: =VLOOKUP(B17,'Component Master'!B:D,3,0) -> Flysky FS-i6S 2.4GHz 10CH AFHDS 2A RC Transmitter With FS-iA10B 10CH Receiver | D17: 1 | E17: Macfos | F17: 45420 | G17: 4809.52 | H17: =G17*D17 -> 4809.52 | I17: =0.05*H17 -> 240.476 | J17: 40.57 | K17: =H17+I17+J17 -> 5090.566 | L17: P0003
A18: 45422 | B18: Aero0173 | C18: =VLOOKUP(B18,'Component Master'!B:D,3,0) -> Hall Sensor | D18: 1 | E18: Macfos | F18: 45420 | G18: 25571.43 | H18: =G18*D18 -> 25571.43 | I18: =0.05*H18 -> 1278.5715 | J18: 40.57 | K18: =H18+I18+J18 -> 26890.571 | L18: P0003
A19: 45422 | B19: Aero0020 | C19: =VLOOKUP(B19,'Component Master'!B:D,3,0) -> Pixhawk Dampner plate | D19: 4 | E19: Macfos | F19: 45420 | G19: 148.305 | H19: =G19*D19 -> 593.22 | I19: =0.18*H19 -> 106.7796 | J19: 40.57 | K19: =H19+I19+J19 -> 740.5696 | L19: P0003
A20: 45422 | B20: Aero0175 | C20: =VLOOKUP(B20,'Component Master'!B:D,3,0) -> High Quality Ultra Flexible 8AWG Silicon Wire 2m (Black) | D20: 2 | E20: Macfos | F20: 45420 | G20: 555.085 | H20: =G20*D20 -> 1110.17 | I20: =0.18*H20 -> 199.8306 | J20: 40.57 | K20: =H20+I20+J20 -> 1350.5706 | L20: P0003
A21: 45422 | B21: Aero0176 | C21: =VLOOKUP(B21,'Component Master'!B:D,3,0) -> Amass XT60-U Female Bullet Connector | D21: 10 | E21: Macfos | F21: 45420 | G21: 29.661 | H21: =G21*D21 -> 296.61 | I21: =0.18*H21 -> 53.3898 | J21: 40.57 | K21: =H21+I21+J21 -> 390.5698 | L21: P0003
A22: 45422 | B22: Aero0177 | C22: =VLOOKUP(B22,'Component Master'!B:D,3,0) -> Amass XT60-U Male Bullet Connector | D22: 10 | E22: Macfos | F22: 45420 | G22: 29.661 | H22: =G22*D22 -> 296.61 | I22: =0.18*H22 -> 53.3898 | J22: 40.57 | K22: =H22+I22+J22 -> 390.5698 | L22: P0003
A23: 45422 | B23: Aero0171 | C23: =VLOOKUP(B23,'Component Master'!B:D,3,0) -> CF Sheet 500*500mm*3mm | D23: 2 | E23: Macfos | F23: 45420 | G23: 7428.815 | H23: =G23*D23 -> 14857.63 | I23: =0.18*H23 -> 2674.3734 | J23: 40.57 | K23: =H23+I23+J23 -> 17572.573 | L23: P0003
A24: 45426 | B24: Aero0029 | C24: =VLOOKUP(B24,'Component Master'!B:D,3,0) -> 3D Printed Parts | D24: 2 | E24: Amuse | F24: 45425 | G24: 282.9 | H24: =G24*D24 -> 565.8 | I24: =0.18*H24 -> 101.844 | J24: 0 | K24: =H24+I24+J24 -> 667.644 | L24: P0001
A25: 45426 | B25: Aero0029 | C25: =VLOOKUP(B25,'Component Master'!B:D,3,0) -> 3D Printed Parts | D25: 2 | E25: Amuse | F25: 45425 | G25: 2492.8 | H25: =G25*D25 -> 4985.6 | I25: =0.18*H25 -> 897.408 | J25: 0 | K25: =H25+I25+J25 -> 5883.008 | L25: P0001
A26: 45428 | B26: Aero0029 | C26: =VLOOKUP(B26,'Component Master'!B:D,3,0) -> 3D Printed Parts | D26: 1 | E26: Nextgen | F26: 45428 | G26: 21750 | H26: =G26*D26 -> 21750 | I26: =0.18*H26 -> 3915 | J26: 118 | K26: =H26+I26+J26 -> 25783 | L26: P0001
A27: 45428 | B27: Aero0029 | C27: =VLOOKUP(B27,'Component Master'!B:D,3,0) -> 3D Printed Parts | D27: 1 | E27: Nextgen | F27: 45428 | G27: 6300 | H27: 6300 | I27: =0.18*H27 -> 1134 | J27: 118 | K27: =H27+I27+J27 -> 7552 | L27: P0001
A28: 45429 | B28: Aero0173 | C28: =VLOOKUP(B28,'Component Master'!B:D,3,0) -> Hall Sensor | D28: 3 | E28: Vyom Drones | F28: 45426 | G28: 4420 | H28: =G28*D28 -> 13260 | I28: =0.05*H28 -> 663 | J28: 0 | K28: =H28+I28+J28 -> 13923 | L28: P0001
A29: 45429 | B29: Aero0183 | C29: =VLOOKUP(B29,'Component Master'!B:D,3,0) -> Water flow sensor-White | D29: 2 | E29: Macfos | F29: 45427 | G29: 189.83 | H29: =G29*D29 -> 379.66 | I29: =0.18*H29 -> 68.3388 | J29: 74 | K29: =H29+I29+J29 -> 521.9988 | L29: P0001
A30: 45430 | B30: Aero0181 | C30: =VLOOKUP(B30,'Component Master'!B:D,3,0) -> Mauch 084: 4-14S BEC | D30: 2 | E30: Vyom Drones | F30: 45427 | G30: 3900 | H30: =G30*D30 -> 7800 | I30: =0.05*H30 -> 390 | J30: 0 | K30: =H30+I30+J30 -> 8190 | L30: P0001
A31: 45430 | B31: Aero0182 | C31: =VLOOKUP(B31,'Component Master'!B:D,3,0) -> Mauch 086: Adapter cable for Pixhawk 2 | D31: 2 | E31: Vyom Drones | F31: 45427 | G31: 500 | H31: =G31*D31 -> 1000 | I31: =0.05*H31 -> 50 | J31: 0 | K31: =H31+I31+J31 -> 1050 | L31: P0001
A32: 45432 | B32: Aero0162 | C32: =VLOOKUP(B32,'Component Master'!B:D,3,0) -> 400mm*380mm*3mm | D32: 2 | E32: Hindustan Engineers | F32: 45430 | G32: 4907 | H32: =G32*D32 -> 9814 | I32: =0.18*H32 -> 1766.52 | J32: 0 | K32: =H32+I32+J32 -> 11580.52 | L32: P0001
A33: 45433 | B33: Aero0170 | C33: =VLOOKUP(B33,'Component Master'!B:D,3,0) -> EFT E610P Airframe with 10L Tank | D33: 1 | E33: Macfos | F33: 45427 | G33: 38903.81 | H33: =G33*D33 -> 38903.81 | I33: =0.05*H33 -> 1945.1905 | J33: 600 | K33: =H33+I33+J33 -> 41449.001 | L33: P0001
A34: 45433 | B34: Aero0171 | C34: =VLOOKUP(B34,'Component Master'!B:D,3,0) -> CF Sheet 500*500mm*3mm | D34: 2 | E34: Macfos | F34: 45427 | G34: 7316.95 | H34: =G34*D34 -> 14633.9 | I34: =0.18*H34 -> 2634.102 | J34: 600 | K34: =H34+I34+J34 -> 17868.002 | L34: P0001
A35: 45434 | B35: Aero0027 | C35: =VLOOKUP(B35,'Component Master'!B:D,3,0) -> Alind water jet cutting | D35: 2 | E35: Alind | F35: 45434 | G35: 1079 | H35: =G35*D35 -> 2158 | I35: =0.12*H35 -> 258.96 | J35: 0 | K35: =H35+I35+J35 -> 2416.96 | L35: P0001
A36: 45434 | B36: Aero0027 | C36: =VLOOKUP(B36,'Component Master'!B:D,3,0) -> Alind water jet cutting | D36: 2 | E36: Alind | F36: 45434 | G36: 1100 | H36: =G36*D36 -> 2200 | I36: =0.12*H36 -> 264 | J36: 0 | K36: =H36+I36+J36 -> 2464 | L36: P0001
A37: 45435 | B37: Aero0172 | C37: =VLOOKUP(B37,'Component Master'!B:D,3,0) -> Aluminium mount | D37: 12 | E37: Aerotek | F37: 45435 | G37: 2750 | H37: =G37*D37 -> 33000 | I37: 6048 | J37: 600 | K37: =H37+I37+J37 -> 39648 | L37: P0001
A38: 45436 | B38: Aero0027 | C38: =VLOOKUP(B38,'Component Master'!B:D,3,0) -> Alind water jet cutting | D38: 1 | E38: Alind | F38: 45436 | G38: 1100 | H38: =G38*D38 -> 1100 | I38: =0.12*H38 -> 132 | J38: 0 | K38: =H38+I38+J38 -> 1232 | L38: P0001
A39: 45439 | B39: Aero0029 | C39: =VLOOKUP(B39,'Component Master'!B:D,3,0) -> 3D Printed Parts | D39: 1 | E39: Monotech | F39: 45439 | G39: 16425 | H39: =G39*D39 -> 16425 | I39: =0.18*H39 -> 2956.5 | J39: 0 | K39: =H39+I39+J39 -> 19381.5 | L39: P0001
A40: 45439 | B40: Aero0184 | C40: =VLOOKUP(B40,'Component Master'!B:D,3,0) -> Liquid water Level sensor | D40: 3 | E40: Macfos | F40: 45436 | G40: 508.47 | H40: =G40*D40 -> 1525.41 | I40: =0.18*H40 -> 274.5738 | J40: 62 | K40: =H40+I40+J40 -> 1861.9838 | L40: P0001
...

Sheet Outward
A1: Date | B1: CID/SKU Number | C1: Client | D1: Client details | E1: Product | F1: Project
B2: Aero0001
B3: Aero0002
B4: Aero0003
B5: Aero0004
B6: Aero0005
B7: Aero0006
B8: Aero0007
B9: Aero0008
B10: Aero0009
B11: Aero0010
B12: Aero0011
B13: Aero0012
... B148: Aero0147

Sheet Workings
A1: S.No | B1: Date | C1: Vendor | D1: Total Price | E1: Project | F1: Remarks
A2: 1 | B2: 45425 | C2: Macfos | D2: =SUMIF('Order Tracker'!G2:G6,C2,'Order Tracker'!L2:L6) -> 59317.003 | E2: NRSC & AGRI-P0001 | F2: -
A3: 2 | B3: 45425 | C3: Hindustan Engineers | D3: =SUMIF('Order Tracker'!G3:G7,C3,'Order Tracker'!L3:L7) -> 11580.52 | E3: AGRI-P0001 | F3: -
A4: 3 | B4: 45425 | C4: Apico | D4: =SUMIF('Order Tracker'!G4:G8,C4,'Order Tracker'!L4:L8) -> 178180 | E4: AGRI-P0001 | F4: Payment processed for 75,000
A5: 4 | B5: 45426 | C5: Aerotek | D5: =SUMIF('Order Tracker'!G5:G9,C5,'Order Tracker'!L5:L9) -> 56640 | E5: AGRI-P0001
A6: 5 | B6: 45426 | C6: Vyom Drones | D6: =SUMIF('Order Tracker'!G6:G10,C6,'Order Tracker'!L6:L10) -> 23163 | E6: AGRI-P0001
A7: 6 | B7: 45427 | C7: Vyom Drones | D7: 9240 | E7: AGRI-P0001
A8: 7 | B8: 45427 | C8: Macfos | D8: 522 | E8: AGRI-P0001 | F8: Online order/COD
A9: 8 | B9: 45433 | C9: Apico | D9: 121625 | E9: AGRI-P0001
A10: 9 | B10: 45432 | C10: Nextgen | D10: 33335 | E10: AGRI-P0001 | F10: Material received
A11: 10 | B11: 45432 | C11: Amuse | D11: 6550.64 | E11: AGRI-P0001 | F11: Material received
A12: 11 | B12: 45435 | C12: Alind | D12: =SUMIF('Order Tracker'!G12:G103,C12,'Order Tracker'!L12:L1000) -> 13408.64 | E12: AGRI-P0001 | F12: Material received
A13: 12 | B13: 45435 | C13: Macfos | D13: =SUMIF('Order Tracker'!G13:G104,C13,'Order Tracker'!L13:L1001) -> 50775.748 | E13: AGRI-P0001 | F13: Online order/COD
A14: 13 | B14: 45435 | C14: Elecdrone Technologies | D14: =SUMIF('Order Tracker'!G14:G110,C14,'Order Tracker'!L14:L1002) -> 657549.92 | E14: AGRI-P0001 | F14: Material received
A15: 14 | B15: 45435 | C15: Aerotek | D15: =SUMIF('Order Tracker'!G15:G111,C15,'Order Tracker'!L15:L1003) -> 147618 | E15: AGRI-P0001 | F15: Carrycase & Aluminium mount-Material received - Payment from Aalayam Contructions
A16: 15 | B16: 45435 | C16: Apico | D16: 76000 | E16: AGRI-P0001 | F16: Project completed
A17: 16 | B17: 45436 | C17: Monotech | D17: =SUMIF('Order Tracker'!G17:G113,C17,'Order Tracker'!L17:L1005) -> 19381.5 | E17: AGRI-P0001 | F17: Payment from Aalayam constructions
A18: 17 | B18: 45436 | C18: Dynamic Calibration | D18: =SUMIF('Order Tracker'!G12:G120,C18,'Order Tracker'!L12:L1006) -> 6962 | E18: AGRI-P0001 | F18: Calibration Testing for measuring instruments
A19: 18 | B19: 45436 | C19: Elecdrone Technologies | D19: =SUMIF('Order Tracker'!G23:G121,C19,'Order Tracker'!L23:L1007) -> 663389.42 | E19: AGRI-P0001 | F19: PUMP
A20: 19 | B20: 45436 | C20: Alind | D20: =SUMIF('Order Tracker'!G24:G122,C20,'Order Tracker'!L24:L1008) -> 13021.12 | E20: AGRI-P0001 | F20: Top Plate
A21: 20 | B21: 45441 | C21: Apico | D21: 21835 | E21: AGRI-P0001 | F21: Material received/Payment from Aalayam constructions
A22: 21 | B22: 45441 | C22: Nextgen | D22: =SUMIF('Order Tracker'!G26:G124,C22,'Order Tracker'!L26:L1010) -> 135386.4 | E22: AGRI-P0001 | F22: Material received/Payment from Aalayam constructions
A23: 22 | B23: 45441 | C23: Amuse | D23: =SUMIF('Order Tracker'!G27:G125,C23,'Order Tracker'!L27:L1011) -> 12735.516 | E23: AGRI-P0001 | F23: Material received/Payment from Aalayam constructions
A24: 23 | B24: 45444 | C24: Alind | D24: =SUMIF('Order Tracker'!G28:G125,C24,'Order Tracker'!L28:L1012) -> 11789.12 | E24: AGRI-P0001 | F24: Material received
A25: 24 | B25: 45447 | C25: Elecdrone Technologies | D25: =SUMIF('Order Tracker'!G28:G125,C25,'Order Tracker'!L28:L1012) -> 657039.02 | E25: AGRI-P0001 | F25: Payment from Aalayam constructions
A26: 25 | B26: 45447 | C26: Macfos | D26: =SUMIF('Order Tracker'!G29:G125,C26,'Order Tracker'!L29:L1013) -> 47565.743 | E26: AGRI-P0001 | F26: Payment from Aalayam constructions
A27: 26 | B27: 45454 | C27: Elecdrone Technologies | D27: 5134.52 | E27: AGRI-P0001 | F27: Payment from Aalayam constructions
A28: 27 | B28: 45454 | C28: Apico | D28: 104250 | E28: AGRI-P0001 | F28: Payment from Aalayam constructions
A29: 28 | B29: 45454 | C29: Yaan Infotech | D29: 18738.4 | E29: Inventory | F29: For Label stickers
A30: 29 | B30: 45464 | C30: Dynamic Calibration | D30: 9204 | E30: AGRI-P0001 | F30: Calibration Testing for measuring instruments
A31: 30 | B31: 45464 | C31: Macfos | D31: 32719 | E31: AGRI-P0001 | F31: For Obstacle avoidance sensor ship it to PDRL

Sheet Notes
A1: Terms | B1: Full form/Understanding
A2: Yes | B2: Possibility of usage in the Drone
A3: No | B3: It will not be used in the Drone
A4: Numbers | B4: Defines the quantity, that will be used in the Drone
A5: Project Specific | B5: Depends on the project needs
A6: Availability | B6: It shows how much quantity is available in the Inventory
A7: P0001,P0002,P0003 | B7: Represents Materials assigned to the project

Sheet Flight test
A1: S.No | B1: Date | C1: Project | D1: Product | E1: Team Members | F1: Starting Time | G1: Return Time | H1: Cab Number | I1: Cab Driver Details | J1: Location | K1: Total Amount
A2: 1 | B2: 45490 | C2: P0002 | D2: CRRI | E2: Hari,Gokul,Balaji | F2: 7:10AM | G2: 0.89583333 | H2: TN05 CR9226 | I2: Prasanth- 6369940114 | J2: Nagari,Chittor | K2: 6960
A3: 2 | B3: 45491 | C3: P0006 | D3: BHIMA | E3: Balaji,Arun,Revanth,Gokul | F3: 10:00AM | G3: 7:30PM | H3: TN04 BD2431 | I3: Karthick-7358313385 | J3: Padappai | K3: 4200
A4: 3 | B4: 45491 | C4: P0006 | D4: BHIMA | E4: Balaji,Arun,Revanth,Gokul | F4: 10:00AM | G4: 7:30PM | H4: TN45 BK 0983 | I4: Selva-9600634465 | J4: Padappai | K4: 2250
A5: 4 | B5: 45493 | C5: P0006 | D5: BHIMA | E5: Balaji,Arun,Revanth,Gokul | F5: 7:10AM | G5: 5:00PM | H5: TN04 BD2431 | I5: Karthick-7358313385 | J5: Padappai | K5: 4200
A6: 5 | B6: 45493 | C6: P0006 | D6: BHIMA | E6: Balaji,Arun,Revanth,Gokul | F6: 7:10AM | G6: 5:00PM | H6: TN48 AR6286 | I6: Ram- 9384759298 | J6: Padappai | K6: 2750
A7: 6 | B7: 45493 | C7: P0006 | D7: BHIMA | E7: Santhosh & Client visit | F7: 12:30PM | G7: 5:00PM | H7: TN67 BQ6822 | I7: Ajmal- 7094623223 | J7: Padappai | K7: 3180
A8: 7 | B8: 45496 | C8: P0002 | D8: CRRI | E8: Deepak,Gokul,Balaji,Ganesnan | F8: 06:20AM | G8: 5:35PM | H8: TN06 C6526 | I8: Arul - 88385 70451 | J8: Nagari,Chittor | K8: 6850
A9: 8 | B9: 45497 | C9: P0006 | D9: BHIMA & CRRI | E9: Balaji, Gokul, Aksash & Hari | F9: 06:30AM | G9: 03:30PM | H9: TN 48 BH0750 | I9: Raj Kumar- 9884847827 | J9: Padappai | K9: 2450
A10: 9 | B10: 45497 | C10: P0006 | D10: BHIMA | E10: Balaji,Arun,Revanth,Gokul | F10: 7:10AM | G10: 5:00PM | H10: TN04 BD2431 | I10: Karthick-7358313385 | J10: Padappai | K10: 4200
A11: 10 | B11: 45500 | C11: P0006 | D11: BHIMA | E11: Gokul,Arun,Revanth & Exicom team | F11: 7:10AM | G11: 7:40PM | H11: TN22CJ8048 | I11: Vijayakumar-9786039559 | J11: Padappai | K11: 4550
A12: 11 | B12: 45500 | C12: P0006 | D12: BHIMA | E12: Gokul,Arun,Revanth & Exicom team | F12: 7:10AM | G12: 7:40PM | H12: TN04 BD2431 | I12: Karthick-7358313385 | J12: Padappai | K12: 4200
A13: 12 | B13: 45504 | C13: P0006 | D13: BHIMA & CRRI | E13: Balaji, Arun, Hari, Vedanth & Akash | F13: 0.27083333 | G13: 03:35PM | H13: TN48 AR6286 | I13: Ram- 9384759298 | J13: Padappai | K13: 2750
A14: 13 | B14: 45504 | C14: P0006 | D14: BHIMA & CRRI | E14: Balaji, Arun, Hari, Vedanth & Akash | F14: 0.27083333 | G14: 03:35PM | H14: TN04 BD2431 | I14: Karthick-7358313385 | J14: Padappai | K14: 4200
A15: 14 | B15: 45507 | C15: P0002 | D15: CRRI | E15: Balaji,Gokul,Deepak and Sumit(CRRI) | F15: 06:50AM | G15: 9:30PM | H15: TN06M 3056 | I15: Pradeep- 9597856428 | J15: Nagari,Chittor | K15: 6910

Sheet Tables
A1: Inventory | C1: BOM product list
A2: SKU | B2: Qty | C2: SKU | D2: Qty
H110: Airframe
H111: Communication
H112: Electricals
H113: Electronics
H114: Payload
E206: Airframe
E207: Airframe
E208: Airframe
E209: Airframe
E210: Airframe
E211: Airframe
E212: Electronics
E213: Electronics
E214: Electronics
E215: Airframe
E216: Airframe
E217: Airframe
... E237: Electricals
